<?xml version="1.0"?>
<robot name="bainan_1">

    <!-- Robot Footprint -->
  <link name="base_footprint"/>

  <joint name="base_joint" type="fixed">
    <parent link="base_footprint"/>
    <child link="base_link"/>
    <origin xyz="0.0 0.0 0.343" rpy="0 0 0"/>
  </joint>

  <!-- base link -->
  <link name="base_link">
  	<visual>
      <origin xyz="0 0 0.0" rpy="0 0 0"/>
      <geometry>
		<box size="0.75 0.75 0.39"/>
      </geometry>
      <material name="blue">
      	<color rgba="0.1 0.1 1.0 0.5" /> 
      </material>
    </visual>
    <collision>
      <origin xyz="0 0 0.0" rpy="0 0 0"/>
      <geometry>
		<box size="0.75 0.75 0.39"/>
      </geometry>
      <material name="blue">
      	<color rgba="0.1 0.1 1.0 0.5" /> 
      </material>
    </collision>
    <inertial>
      <mass value="25"/>
      <inertia ixx="1.30" ixy="0" ixz="0" iyy="1.30" iyz="0" izz="0.551"/>
    </inertial>
  </link>
    
  <!-- laser link -->
  <link name="laser_link">
    <visual>
      <origin xyz="0 0 0" rpy="0 0 0"/>
      <geometry>
        <cylinder length="0.084" radius="0.031"/>
      </geometry>
      <material name="black">
        <color rgba="0.0 0.0 0.0 0.5" /> 
      </material>
    </visual>
    <collision>
      <origin xyz="0 0 0" rpy="0 0 0"/>
      <geometry>
        <cylinder length="0.084" radius="0.031"/>
      </geometry>
      <material name="black">
        <color rgba="0.0 0.0 0.0 0.5" /> 
      </material>
    </collision>
    <inertial>
    <mass value="0.1"/>
      <inertia ixx="0.000190416666667" ixy="0" ixz="0" iyy="0.0001904" iyz="0" izz="0.00036"/>
    </inertial>
  </link>
  
  <!-- laser joint -->
  <joint name="laser_joint" type="fixed">
      <parent link="base_link" />
      <child link="laser_link" />
      <origin xyz="0.317 0 -0.075" />
  </joint>

  <link name="imu_link">
  	<visual>
      <origin xyz="0 0 0.0" rpy="0 0 0"/>
      <geometry>
		    <box size="0.02 0.02 0.02"/>
      </geometry>
    </visual>
    <collision>
      <origin xyz="0 0 0.0" rpy="0 0 0"/>
      <geometry>
		    <box size="0.02 0.02 0.02"/>
      </geometry>
    </collision>
    <inertial>
      <mass value="0.1"/>
        <inertia ixx="0.000190416666667" ixy="0" ixz="0" iyy="0.0001904" iyz="0" izz="0.00036"/>
      </inertial>
  </link>

  <!-- imu joint -->
  <joint name="imu_joint" type="fixed">
      <parent link="base_link" />
      <child link="imu_link" />
      <origin xyz="-0.205 0 0" />
  </joint>


  <!-- camera_link 前上-->
  <link name="camera1_depth_frame">
  <visual>
    <origin xyz="0 0 0.0" rpy="0 0 0"/>
    <geometry>
      <box size="0.02510 0.08982 0.02510"/>
    </geometry>
  </visual>
  <collision>
    <origin xyz="0 0 0.0" rpy="0 0 0"/>
    <geometry>
      <box size="0.02 0.02 0.02"/>
    </geometry>
  </collision>
  <inertial>
    <mass value="0.1"/>
      <inertia ixx="0.000190416666667" ixy="0" ixz="0" iyy="0.0001904" iyz="0" izz="0.00036"/>
    </inertial>
  </link>

  <!-- camera_joint 前上-->
  <joint name="camera1_joint" type="fixed">
      <parent link="base_link" />
      <child link="camera1_depth_frame" />
      <origin xyz="0.375 0 0.097" rpy="0 0 0"/>
  </joint>

  <!-- camera_link 前下-->
  <link name="camera2_depth_frame">
  <visual>
    <origin xyz="0 0 0.0" rpy="0 0 0"/>
    <geometry>
      <box size="0.02510 0.08982 0.02510"/>
    </geometry>
  </visual>
  <collision>
    <origin xyz="0 0 0.0" rpy="0 0 0"/>
    <geometry>
      <box size="0.02 0.02 0.02"/>
    </geometry>
  </collision>
  <inertial>
    <mass value="0.1"/>
      <inertia ixx="0.000190416666667" ixy="0" ixz="0" iyy="0.0001904" iyz="0" izz="0.00036"/>
    </inertial>
  </link>

  <!-- camera_joint 前下-->
  <joint name="camera2_joint" type="fixed">
      <parent link="base_link" />
      <child link="camera2_depth_frame" />
      <origin xyz="0.363 0 0" rpy="0 0.789 0"/>
  </joint>

  <!-- camera_link 后-->
  <link name="camera3_depth_frame">
  <visual>
    <origin xyz="0 0 0.0" rpy="0 0 0"/>
    <geometry>
      <box size="0.02510 0.08982 0.02510"/>
    </geometry>
  </visual>
  <collision>
    <origin xyz="0 0 0.0" rpy="0 0 0"/>
    <geometry>
      <box size="0.02 0.02 0.02"/>
    </geometry>
  </collision>
  <inertial>
    <mass value="0.1"/>
      <inertia ixx="0.000190416666667" ixy="0" ixz="0" iyy="0.0001904" iyz="0" izz="0.00036"/>
    </inertial>
  </link>

  <!-- camera_joint 后-->
  <joint name="camera3_joint" type="fixed">
      <parent link="base_link" />
      <child link="camera3_depth_frame" />
      <origin xyz="-0.375 0 0.097" rpy="0 0 3.14"/>
  </joint>


  <!-- ultrasonic_sensor_link1 -->
  <link name="ultrasonic_sensor_link1">
    <visual>
      <origin xyz="0 0 0.0" rpy="0 1.57079 0"/>
      <geometry>
        <cylinder length="0.01995" radius="0.0124"/>
      </geometry>
    </visual>
    <collision>
      <origin xyz="0 0 0.0" rpy="0 1.57079 0"/>
      <geometry>
        <cylinder length="0.01995" radius="0.0124"/>
      </geometry>
    </collision>
    <inertial>
      <mass value="0.1"/>
        <inertia ixx="0.000190416666667" ixy="0" ixz="0" iyy="0.0001904" iyz="0" izz="0.00036"/>
      </inertial>
  </link>

  <!-- ultrasonic_sensor_joint1 -->
  <joint name="ultrasonic_sensor_joint1" type="fixed">
      <parent link="base_link" />
      <child link="ultrasonic_sensor_link1" />
      <origin xyz="0.322 0.322 0.05" rpy="0 0 0.789"/>
  </joint>

  <!-- ultrasonic_sensor_link2 -->
  <link name="ultrasonic_sensor_link2">
  	<visual>
      <origin xyz="0 0 0.0" rpy="0 1.57079 0"/>
      <geometry>
		    <cylinder length="0.01995" radius="0.0124"/>
      </geometry>
    </visual>
    <collision>
      <origin xyz="0 0 0.0" rpy="0 1.57079 0"/>
      <geometry>
		    <cylinder length="0.01995" radius="0.0124"/>
      </geometry>
    </collision>
    <inertial>
      <mass value="0.1"/>
        <inertia ixx="0.000190416666667" ixy="0" ixz="0" iyy="0.0001904" iyz="0" izz="0.00036"/>
      </inertial>
  </link>

  <!-- ultrasonic_sensor_joint2 -->
  <joint name="ultrasonic_sensor_joint2" type="fixed">
      <parent link="base_link" />
      <child link="ultrasonic_sensor_link2" />
      <origin xyz="0.375 0  0.05" />
  </joint>

  <!-- ultrasonic_sensor_link3 -->
  <link name="ultrasonic_sensor_link3">
    <visual>
      <origin xyz="0 0 0.0" rpy="0 1.57079 0"/>
      <geometry>
        <cylinder length="0.01995" radius="0.0124"/>
      </geometry>
    </visual>
    <collision>
      <origin xyz="0 0 0.0" rpy="0 1.57079 0"/>
      <geometry>
        <cylinder length="0.01995" radius="0.0124"/>
      </geometry>
    </collision>
    <inertial>
      <mass value="0.1"/>
        <inertia ixx="0.000190416666667" ixy="0" ixz="0" iyy="0.0001904" iyz="0" izz="0.00036"/>
      </inertial>
  </link>

  <!-- ultrasonic_sensor_joint3 -->
  <joint name="ultrasonic_sensor_joint3" type="fixed">
      <parent link="base_link" />
      <child link="ultrasonic_sensor_link3" />
      <origin xyz="0.322 -0.322 -0.05" rpy="0 0 -0.789"/>
  </joint>

<!-- ultrasonic_sensor_link4 -->
  <link name="ultrasonic_sensor_link4">
  	<visual>
      <origin xyz="0 0 0.0" rpy="0 1.57079 0"/>
      <geometry>
		    <cylinder length="0.01995" radius="0.0124"/>
      </geometry>
    </visual>
    <collision>
      <origin xyz="0 0 0.0" rpy="0 1.57079 0"/>
      <geometry>
		    <cylinder length="0.01995" radius="0.0124"/>
      </geometry>
    </collision>
    <inertial>
      <mass value="0.1"/>
        <inertia ixx="0.000190416666667" ixy="0" ixz="0" iyy="0.0001904" iyz="0" izz="0.00036"/>
      </inertial>
  </link>

  <!-- ultrasonic_sensor_joint4 -->
  <joint name="ultrasonic_sensor_joint4" type="fixed">
      <parent link="base_link" />
      <child link="ultrasonic_sensor_link4" />
      <origin xyz="0 0.375 0.05"  rpy="0 0 1.57"/>
  </joint>

  <!-- ultrasonic_sensor_link5 -->
  <link name="ultrasonic_sensor_link5">
  	<visual>
      <origin xyz="0 0 0.0" rpy="0 1.57079 0"/>
      <geometry>
		    <cylinder length="0.01995" radius="0.0124"/>
      </geometry>
    </visual>
    <collision>
      <origin xyz="0 0 0.0" rpy="0 1.57079 0"/>
      <geometry>
		    <cylinder length="0.01995" radius="0.0124"/>
      </geometry>
    </collision>
    <inertial>
      <mass value="0.1"/>
        <inertia ixx="0.000190416666667" ixy="0" ixz="0" iyy="0.0001904" iyz="0" izz="0.00036"/>
      </inertial>
  </link>

  <!-- ultrasonic_sensor_joint5 -->
  <joint name="ultrasonic_sensor_joint5" type="fixed">
      <parent link="base_link" />
      <child link="ultrasonic_sensor_link5" />
      <origin xyz="-0.322 0.322 0.05"  rpy="0 0 2.335"/>
  </joint>

  <!-- ultrasonic_sensor_link6 -->
  <link name="ultrasonic_sensor_link6">
  	<visual>
      <origin xyz="0 0 0.0" rpy="0 1.57079 0"/>
      <geometry>
		    <cylinder length="0.01995" radius="0.0124"/>
      </geometry>
    </visual>
    <collision>
      <origin xyz="0 0 0.0" rpy="0 1.57079 0"/>
      <geometry>
		    <cylinder length="0.01995" radius="0.0124"/>
      </geometry>
    </collision>
    <inertial>
      <mass value="0.1"/>
        <inertia ixx="0.000190416666667" ixy="0" ixz="0" iyy="0.0001904" iyz="0" izz="0.00036"/>
      </inertial>
  </link>

  <!-- ultrasonic_sensor_joint6 -->
  <joint name="ultrasonic_sensor_joint6" type="fixed">
      <parent link="base_link" />
      <child link="ultrasonic_sensor_link6" />
      <origin xyz="-0.322 -0.322 0.05"  rpy="0 0 -2.335"/>
  </joint>

  <!-- ultrasonic_sensor_link7 -->
  <link name="ultrasonic_sensor_link7">
  	<visual>
      <origin xyz="0 0 0.0" rpy="0 1.57079 0"/>
      <geometry>
		    <cylinder length="0.01995" radius="0.0124"/>
      </geometry>
    </visual>
    <collision>
      <origin xyz="0 0 0.0" rpy="0 1.57079 0"/>
      <geometry>
		    <cylinder length="0.01995" radius="0.0124"/>
      </geometry>
    </collision>
    <inertial>
      <mass value="0.1"/>
        <inertia ixx="0.000190416666667" ixy="0" ixz="0" iyy="0.0001904" iyz="0" izz="0.00036"/>
      </inertial>
  </link>

  <!-- ultrasonic_sensor_joint7 -->
  <joint name="ultrasonic_sensor_joint7" type="fixed">
      <parent link="base_link" />
      <child link="ultrasonic_sensor_link7" />
      <origin xyz="0 -0.375 0.05"  rpy="0 0 -1.57"/>
  </joint>

  <link name="left_wheel_link">
      <visual>
        <origin xyz="0 0 0" rpy="1.57079 0 0"/>
        <geometry>
          <cylinder length="0.039" radius="0.075"/>
        </geometry>
          <material name="black">
            <color rgba="0.0 0.0 0.0 0.5" /> 
          </material>
      </visual>
      <collision>
        <origin xyz="0 0 0" rpy="1.57079 0 0"/>
        <geometry>
          <cylinder length="0.039" radius="0.075"/>
        </geometry>
          <material name="black">
            <color rgba="0.0 0.0 0.0 0.5" /> 
          </material>
      </collision>
      <inertial>
        <mass value="0.2"/>
          <inertia ixx="0.000190416666667" ixy="0" ixz="0" iyy="0.0001904" iyz="0" izz="0.00036"/>
        </inertial>
  </link>
    
  <link name="right_wheel_link">
      <visual>
        <origin xyz="0 0 0" rpy="1.57079 0 0"/>
        <geometry>
          <cylinder length="0.039" radius="0.075"/>
        </geometry>
          <material name="black">
            <color rgba="0.0 0.0 0.0 0.5" /> 
          </material>
      </visual>
      <collision>
        <origin xyz="0 0 0" rpy="1.57079 0 0"/>
        <geometry>
          <cylinder length="0.039" radius="0.075"/>
        </geometry>
          <material name="black">
            <color rgba="0.0 0.0 0.0 0.5" /> 
          </material>
      </collision>
      <inertial>
      <mass value="0.2"/>
      <inertia ixx="0.000190416666667" ixy="0" ixz="0" iyy="0.0001904" iyz="0" izz="0.00036"/>
    </inertial>
  </link>
    
  <joint name="left_wheel_joint" type="continuous">
      <parent link="base_link" />
      <child link="left_wheel_link" />
      <origin xyz="0 0.375 -0.268" />
      <axis xyz="0 1 0" />
  </joint>

  <joint name="right_wheel_joint" type="continuous">
      <parent link="base_link" />
      <child link="right_wheel_link" />
      <origin xyz="0 -0.375 -0.268" />
      <axis xyz="0 1 0" />
  </joint>

  <link name="front_caster_link">
      <visual>
        <origin xyz="0 0 0" rpy="0 0 0"/>
        <geometry>
            <sphere radius="0.065"/>
        </geometry>
          <material name="black">
            <color rgba="0.0 0.0 0.0 0.5" /> 
          </material>
      </visual>
      <collision>
        <origin xyz="0 0 0" rpy="0 0 0"/>
        <geometry>
            <sphere radius="0.065"/>
        </geometry>
          <material name="black">
            <color rgba="0.0 0.0 0.0 0.5" /> 
          </material>
      </collision>
      <inertial>
      <mass value="0.02"/>
      <inertia ixx="0.000190416666667" ixy="0" ixz="0" iyy="0.0001904" iyz="0" izz="0.00036"/>
    </inertial>
  </link>
    
  <joint name="front_caster_joint" type="fixed">
      <parent link="base_link" />
      <child link="front_caster_link" />
      <origin xyz="0.256 0.223 -0.268" />
      <axis xyz="1 0 0" />
  </joint>

  <link name="back_caster_link">
      <visual>
        <origin xyz="0 0 0" rpy="0 0 0"/>
        <geometry>
            <sphere radius="0.065"/>
        </geometry>
          <material name="black">
            <color rgba="0.0 0.0 0.0 0.5" /> 
          </material>
      </visual>
      <collision>
        <origin xyz="0 0 0" rpy="0 0 0"/>
        <geometry>
            <sphere radius="0.065"/>
        </geometry>
          <material name="black">
            <color rgba="0.0 0.0 0.0 0.5" /> 
          </material>
      </collision>
      <inertial>
      <mass value="0.02"/>
      <inertia ixx="0.000190416666667" ixy="0" ixz="0" iyy="0.0001904" iyz="0" izz="0.00036"/>
    </inertial>
  </link>
    
  <joint name="back_caster_joint" type="fixed">
      <parent link="base_link" />
      <child link="back_caster_link" />
      <origin xyz="0.256 -0.223 -0.268" />
      <axis xyz="1 0 0" />
  </joint>

  <link name="left_caster_link">
      <visual>
        <origin xyz="0 0 0" rpy="0 0 0"/>
        <geometry>
            <sphere radius="0.065"/>
        </geometry>
          <material name="black">
            <color rgba="0.0 0.0 0.0 0.5" /> 
          </material>
      </visual>
      <collision>
        <origin xyz="0 0 0" rpy="0 0 0"/>
        <geometry>
            <sphere radius="0.065"/>
        </geometry>
          <material name="black">
            <color rgba="0.0 0.0 0.0 0.5" /> 
          </material>
      </collision>
      <inertial>
      <mass value="0.02"/>
      <inertia ixx="0.000190416666667" ixy="0" ixz="0" iyy="0.0001904" iyz="0" izz="0.00036"/>
    </inertial>
  </link>
    
  <joint name="left_caster_joint" type="fixed">
      <parent link="base_link" />
      <child link="left_caster_link" />
      <origin xyz="-0.256 0.223 -0.268" />
      <axis xyz="1 0 0" />
  </joint>

  <link name="right_caster_link">
      <visual>
        <origin xyz="0 0 0" rpy="0 0 0"/>
        <geometry>
            <sphere radius="0.065"/>
        </geometry>
          <material name="black">
            <color rgba="0.0 0.0 0.0 0.5" /> 
          </material>
      </visual>
      <collision>
        <origin xyz="0 0 0" rpy="0 0 0"/>
        <geometry>
            <sphere radius="0.065"/>
        </geometry>
          <material name="black">
            <color rgba="0.0 0.0 0.0 0.5" /> 
          </material>
      </collision>
      <inertial>
      <mass value="0.02"/>
      <inertia ixx="0.000190416666667" ixy="0" ixz="0" iyy="0.0001904" iyz="0" izz="0.00036"/>
    </inertial>
  </link>
    
  <joint name="right_caster_joint" type="fixed">
      <parent link="base_link" />
      <child link="right_caster_link" />
      <origin xyz="-0.256 -0.223 -0.268" />
      <axis xyz="1 0 0" />
  </joint>
</robot>